Workbook

Sheet Guest List
A1: EVER AFTER — Guest List & Day-Of Check-In
A2: Sample event: Maria & Jon · 14 Feb 2027 · Casa Almendra, Tagaytay
A4: HOW TO USE
A5: · Yellow cells are the ones you fill in. Everything else is a formula — leave it alone.
A6: · Before the day: fill Name, Side, Group, Contact, RSVP, Table, Seat.
A7: · On the day: each checkpoint marshal marks YES in their own column as guests pass.
A8: · Set RSVP to Accepted / Declined / No reply. Declined guests drop off the Attendee Sheet automatically.
A9: · Print the Attendee Sheet tab as your paper backup for each checkpoint.
A11: Guest Name | B11: Side | C11: Group | D11: Contact | E11: RSVP | F11: Table | G11: Seat | H11: 1. Arrival | I11: 2. Gift Table | J11: 3. Giveaways | K11: Notes
A12: Ana Reyes | B12: Bride | C12: Family | D12: 0917 555 0101 | E12: Accepted | F12: 1 | G12: 1 | H12: YES | I12: YES | J12: YES
A13: Ramon Reyes | B13: Bride | C13: Family | D13: 0917 555 0102 | E13: Accepted | F13: 1 | G13: 2 | H13: YES | I13: YES | J13: YES
A14: Carmela Reyes | B14: Bride | C14: Family | D14: 0917 555 0103 | E14: Accepted | F14: 1 | G14: 3 | H14: YES | I14: YES | K14: Vegetarian
A15: Tito Boy Santos | B15: Bride | C15: Family | D15: 0917 555 0104 | E15: Accepted | F15: 1 | G15: 4 | H15: YES | K15: Needs aisle seat
A16: Grace Villanueva | B16: Bride | C16: Ninang | D16: 0917 555 0105 | E16: Accepted | F16: 2 | G16: 1 | H16: YES | I16: YES | J16: YES | K16: Principal sponsor
A17: Eduardo Cruz | B17: Groom | C17: Ninong | D17: 0917 555 0106 | E17: Accepted | F17: 2 | G17: 2 | H17: YES | I17: YES | K17: Principal sponsor
A18: Lorna Cruz | B18: Groom | C18: Family | D18: 0917 555 0107 | E18: Accepted | F18: 2 | G18: 3 | H18: YES | I18: YES | J18: YES
A19: Miguel Cruz | B19: Groom | C19: Family | D19: 0917 555 0108 | E19: Accepted | F19: 2 | G19: 4 | H19: YES
A20: Patricia Lim | B20: Bride | C20: Bridesmaid | D20: 0917 555 0109 | E20: Accepted | F20: 3 | G20: 1 | H20: YES | I20: YES | J20: YES | K20: Entourage
A21: Katrina Uy | B21: Bride | C21: Bridesmaid | D21: 0917 555 0110 | E21: Accepted | F21: 3 | G21: 2 | H21: YES | I21: YES | J21: YES | K21: Entourage
A22: Joanne Tan | B22: Bride | C22: Bridesmaid | D22: 0917 555 0111 | E22: Accepted | F22: 3 | G22: 3 | H22: YES | K22: Entourage
A23: Paolo Mendoza | B23: Groom | C23: Groomsman | D23: 0917 555 0112 | E23: Accepted | F23: 3 | G23: 4 | H23: YES | I23: YES | J23: YES | K23: Entourage
A24: Rafael Ocampo | B24: Groom | C24: Groomsman | D24: 0917 555 0113 | E24: Accepted | F24: 3 | G24: 5 | H24: YES | I24: YES | K24: Entourage
A25: Dennis Yap | B25: Groom | C25: Groomsman | D25: 0917 555 0114 | E25: Accepted | F25: 3 | G25: 6 | H25: YES | I25: YES | J25: YES | K25: Entourage
A26: Sofia Bautista | B26: Bride | C26: College | D26: 0917 555 0115 | E26: Accepted | F26: 4 | G26: 1 | H26: YES | I26: YES | J26: YES | K26: +1 confirmed
A27: Mark Bautista | B27: Bride | C27: College | D27: 0917 555 0116 | E27: Accepted | F27: 4 | G27: 2 | H27: YES | I27: YES | J27: YES | K27: Plus one of Sofia
A28: Trina Sarmiento | B28: Bride | C28: College | D28: 0917 555 0117 | E28: Accepted | F28: 4 | G28: 3 | H28: YES
A29: Jerome Padilla | B29: Bride | C29: College | D29: 0917 555 0118 | E29: No reply | K29: Follow up by 20 Jan
A30: Bea Fernandez | B30: Bride | C30: College | D30: 0917 555 0119 | E30: Declined | K30: Abroad that week
A31: Nico Aquino | B31: Groom | C31: Work | D31: 0917 555 0120 | E31: Accepted | F31: 5 | G31: 1 | H31: YES | I31: YES | J31: YES
A32: Hannah Dela Cruz | B32: Groom | C32: Work | D32: 0917 555 0121 | E32: Accepted | F32: 5 | G32: 2 | H32: YES | I32: YES
A33: Christian Bello | B33: Groom | C33: Work | D33: 0917 555 0122 | E33: Accepted | F33: 5 | G33: 3 | H33: YES | K33: Arriving late
A34: Angela Navarro | B34: Groom | C34: Work | D34: 0917 555 0123 | E34: Accepted | F34: 5 | G34: 4 | H34: YES | I34: YES | J34: YES
A35: Ruel Domingo | B35: Groom | C35: Work | D35: 0917 555 0124 | E35: No reply | K35: Follow up by 20 Jan
A36: Melissa Ang | B36: Groom | C36: Work | D36: 0917 555 0125 | E36: Declined | K36: Due date same month
A37: Fr. Antonio Reyes | B37: Both | C37: Officiant | D37: 0917 555 0126 | E37: Accepted | H37: YES | K37: Officiant — no table
A38: Liza Gomez | B38: Both | C38: Family Friend | D38: 0917 555 0127 | E38: Accepted | F38: 6 | G38: 1 | H38: YES | I38: YES | J38: YES
A39: Arturo Gomez | B39: Both | C39: Family Friend | D39: 0917 555 0128 | E39: Accepted | F39: 6 | G39: 2 | H39: YES | I39: YES | J39: YES
A40: Cielo Ramos | B40: Both | C40: Family Friend | D40: 0917 555 0129 | E40: Accepted | F40: 6 | G40: 3 | K40: No-show on the day
A41: Benjie Salazar | B41: Both | C41: Family Friend | D41: 0917 555 0130 | E41: Accepted | F41: 6 | G41: 4 | H41: YES | I41: YES

Sheet Live Count
A1: Live Count
A2: Updates automatically from the Guest List tab. Keep this open on the coordinator's phone.
A4: Invited (rows filled) | B4: =COUNTA('Guest List'!$A$12:$A$51) -> 30
A5: Accepted | B5: =COUNTIF('Guest List'!$E$12:$E$51,"Accepted") -> 26
A6: Declined | B6: =COUNTIF('Guest List'!$E$12:$E$51,"Declined") -> 2
A7: No reply | B7: =COUNTIF('Guest List'!$E$12:$E$51,"No reply") -> 2
A9: Arrived (checkpoint 1) | B9: =COUNTIF('Guest List'!$H$12:$H$51,"YES") -> 25
A10: Gift table (checkpoint 2) | B10: =COUNTIF('Guest List'!$I$12:$I$51,"YES") -> 19
A11: Giveaways (checkpoint 3) | B11: =COUNTIF('Guest List'!$J$12:$J$51,"YES") -> 14
A13: Accepted but not arrived | B13: =COUNTIF('Guest List'!$E$12:$E$51,"Accepted")-COUNTIF('Guest List'!$H$12:$H$51,"YES") -> 1
A14: Arrival rate | B14: =IFERROR(COUNTIF('Guest List'!$H$12:$H$51,"YES")/COUNTIF('Guest List'!$E$12:$E$51,"Accepted"),0) -> 0.96153846
A15: Giveaway pickup rate | B15: =IFERROR(COUNTIF('Guest List'!$J$12:$J$51,"YES")/COUNTIF('Guest List'!$H$12:$H$51,"YES"),0) -> 0.56
A17: Note: counts read rows 12–51 of the Guest List tab. Extend these ranges if you add more rows.

Sheet Attendee Sheet
A1: Attendee Sheet — Print This
A2: Paper backup for each checkpoint. Blank rows are declined or unfilled guests — hide or filter them before printing.
A4: Guest Name | B4: Table | C4: Seat | D4: Group | E4: 1. Arrival | F4: 2. Gift | G4: 3. Giveaway
A5: =IF('Guest List'!$E$12="Accepted",'Guest List'!$A$12,"") -> Ana Reyes | B5: =IF('Guest List'!$E$12="Accepted",'Guest List'!$F$12,"") -> 1 | C5: =IF('Guest List'!$E$12="Accepted",'Guest List'!$G$12,"") -> 1 | D5: =IF('Guest List'!$E$12="Accepted",'Guest List'!$C$12,"") -> Family
A6: =IF('Guest List'!$E$13="Accepted",'Guest List'!$A$13,"") -> Ramon Reyes | B6: =IF('Guest List'!$E$13="Accepted",'Guest List'!$F$13,"") -> 1 | C6: =IF('Guest List'!$E$13="Accepted",'Guest List'!$G$13,"") -> 2 | D6: =IF('Guest List'!$E$13="Accepted",'Guest List'!$C$13,"") -> Family
A7: =IF('Guest List'!$E$14="Accepted",'Guest List'!$A$14,"") -> Carmela Reyes | B7: =IF('Guest List'!$E$14="Accepted",'Guest List'!$F$14,"") -> 1 | C7: =IF('Guest List'!$E$14="Accepted",'Guest List'!$G$14,"") -> 3 | D7: =IF('Guest List'!$E$14="Accepted",'Guest List'!$C$14,"") -> Family
A8: =IF('Guest List'!$E$15="Accepted",'Guest List'!$A$15,"") -> Tito Boy Santos | B8: =IF('Guest List'!$E$15="Accepted",'Guest List'!$F$15,"") -> 1 | C8: =IF('Guest List'!$E$15="Accepted",'Guest List'!$G$15,"") -> 4 | D8: =IF('Guest List'!$E$15="Accepted",'Guest List'!$C$15,"") -> Family
A9: =IF('Guest List'!$E$16="Accepted",'Guest List'!$A$16,"") -> Grace Villanueva | B9: =IF('Guest List'!$E$16="Accepted",'Guest List'!$F$16,"") -> 2 | C9: =IF('Guest List'!$E$16="Accepted",'Guest List'!$G$16,"") -> 1 | D9: =IF('Guest List'!$E$16="Accepted",'Guest List'!$C$16,"") -> Ninang
A10: =IF('Guest List'!$E$17="Accepted",'Guest List'!$A$17,"") -> Eduardo Cruz | B10: =IF('Guest List'!$E$17="Accepted",'Guest List'!$F$17,"") -> 2 | C10: =IF('Guest List'!$E$17="Accepted",'Guest List'!$G$17,"") -> 2 | D10: =IF('Guest List'!$E$17="Accepted",'Guest List'!$C$17,"") -> Ninong
A11: =IF('Guest List'!$E$18="Accepted",'Guest List'!$A$18,"") -> Lorna Cruz | B11: =IF('Guest List'!$E$18="Accepted",'Guest List'!$F$18,"") -> 2 | C11: =IF('Guest List'!$E$18="Accepted",'Guest List'!$G$18,"") -> 3 | D11: =IF('Guest List'!$E$18="Accepted",'Guest List'!$C$18,"") -> Family
A12: =IF('Guest List'!$E$19="Accepted",'Guest List'!$A$19,"") -> Miguel Cruz | B12: =IF('Guest List'!$E$19="Accepted",'Guest List'!$F$19,"") -> 2 | C12: =IF('Guest List'!$E$19="Accepted",'Guest List'!$G$19,"") -> 4 | D12: =IF('Guest List'!$E$19="Accepted",'Guest List'!$C$19,"") -> Family
A13: =IF('Guest List'!$E$20="Accepted",'Guest List'!$A$20,"") -> Patricia Lim | B13: =IF('Guest List'!$E$20="Accepted",'Guest List'!$F$20,"") -> 3 | C13: =IF('Guest List'!$E$20="Accepted",'Guest List'!$G$20,"") -> 1 | D13: =IF('Guest List'!$E$20="Accepted",'Guest List'!$C$20,"") -> Bridesmaid
A14: =IF('Guest List'!$E$21="Accepted",'Guest List'!$A$21,"") -> Katrina Uy | B14: =IF('Guest List'!$E$21="Accepted",'Guest List'!$F$21,"") -> 3 | C14: =IF('Guest List'!$E$21="Accepted",'Guest List'!$G$21,"") -> 2 | D14: =IF('Guest List'!$E$21="Accepted",'Guest List'!$C$21,"") -> Bridesmaid
A15: =IF('Guest List'!$E$22="Accepted",'Guest List'!$A$22,"") -> Joanne Tan | B15: =IF('Guest List'!$E$22="Accepted",'Guest List'!$F$22,"") -> 3 | C15: =IF('Guest List'!$E$22="Accepted",'Guest List'!$G$22,"") -> 3 | D15: =IF('Guest List'!$E$22="Accepted",'Guest List'!$C$22,"") -> Bridesmaid
A16: =IF('Guest List'!$E$23="Accepted",'Guest List'!$A$23,"") -> Paolo Mendoza | B16: =IF('Guest List'!$E$23="Accepted",'Guest List'!$F$23,"") -> 3 | C16: =IF('Guest List'!$E$23="Accepted",'Guest List'!$G$23,"") -> 4 | D16: =IF('Guest List'!$E$23="Accepted",'Guest List'!$C$23,"") -> Groomsman
A17: =IF('Guest List'!$E$24="Accepted",'Guest List'!$A$24,"") -> Rafael Ocampo | B17: =IF('Guest List'!$E$24="Accepted",'Guest List'!$F$24,"") -> 3 | C17: =IF('Guest List'!$E$24="Accepted",'Guest List'!$G$24,"") -> 5 | D17: =IF('Guest List'!$E$24="Accepted",'Guest List'!$C$24,"") -> Groomsman
A18: =IF('Guest List'!$E$25="Accepted",'Guest List'!$A$25,"") -> Dennis Yap | B18: =IF('Guest List'!$E$25="Accepted",'Guest List'!$F$25,"") -> 3 | C18: =IF('Guest List'!$E$25="Accepted",'Guest List'!$G$25,"") -> 6 | D18: =IF('Guest List'!$E$25="Accepted",'Guest List'!$C$25,"") -> Groomsman
A19: =IF('Guest List'!$E$26="Accepted",'Guest List'!$A$26,"") -> Sofia Bautista | B19: =IF('Guest List'!$E$26="Accepted",'Guest List'!$F$26,"") -> 4 | C19: =IF('Guest List'!$E$26="Accepted",'Guest List'!$G$26,"") -> 1 | D19: =IF('Guest List'!$E$26="Accepted",'Guest List'!$C$26,"") -> College
A20: =IF('Guest List'!$E$27="Accepted",'Guest List'!$A$27,"") -> Mark Bautista | B20: =IF('Guest List'!$E$27="Accepted",'Guest List'!$F$27,"") -> 4 | C20: =IF('Guest List'!$E$27="Accepted",'Guest List'!$G$27,"") -> 2 | D20: =IF('Guest List'!$E$27="Accepted",'Guest List'!$C$27,"") -> College
A21: =IF('Guest List'!$E$28="Accepted",'Guest List'!$A$28,"") -> Trina Sarmiento | B21: =IF('Guest List'!$E$28="Accepted",'Guest List'!$F$28,"") -> 4 | C21: =IF('Guest List'!$E$28="Accepted",'Guest List'!$G$28,"") -> 3 | D21: =IF('Guest List'!$E$28="Accepted",'Guest List'!$C$28,"") -> College
A22: =IF('Guest List'!$E$29="Accepted",'Guest List'!$A$29,"") | B22: =IF('Guest List'!$E$29="Accepted",'Guest List'!$F$29,"") | C22: =IF('Guest List'!$E$29="Accepted",'Guest List'!$G$29,"") | D22: =IF('Guest List'!$E$29="Accepted",'Guest List'!$C$29,"")
A23: =IF('Guest List'!$E$30="Accepted",'Guest List'!$A$30,"") | B23: =IF('Guest List'!$E$30="Accepted",'Guest List'!$F$30,"") | C23: =IF('Guest List'!$E$30="Accepted",'Guest List'!$G$30,"") | D23: =IF('Guest List'!$E$30="Accepted",'Guest List'!$C$30,"")
A24: =IF('Guest List'!$E$31="Accepted",'Guest List'!$A$31,"") -> Nico Aquino | B24: =IF('Guest List'!$E$31="Accepted",'Guest List'!$F$31,"") -> 5 | C24: =IF('Guest List'!$E$31="Accepted",'Guest List'!$G$31,"") -> 1 | D24: =IF('Guest List'!$E$31="Accepted",'Guest List'!$C$31,"") -> Work
A25: =IF('Guest List'!$E$32="Accepted",'Guest List'!$A$32,"") -> Hannah Dela Cruz | B25: =IF('Guest List'!$E$32="Accepted",'Guest List'!$F$32,"") -> 5 | C25: =IF('Guest List'!$E$32="Accepted",'Guest List'!$G$32,"") -> 2 | D25: =IF('Guest List'!$E$32="Accepted",'Guest List'!$C$32,"") -> Work
A26: =IF('Guest List'!$E$33="Accepted",'Guest List'!$A$33,"") -> Christian Bello | B26: =IF('Guest List'!$E$33="Accepted",'Guest List'!$F$33,"") -> 5 | C26: =IF('Guest List'!$E$33="Accepted",'Guest List'!$G$33,"") -> 3 | D26: =IF('Guest List'!$E$33="Accepted",'Guest List'!$C$33,"") -> Work
A27: =IF('Guest List'!$E$34="Accepted",'Guest List'!$A$34,"") -> Angela Navarro | B27: =IF('Guest List'!$E$34="Accepted",'Guest List'!$F$34,"") -> 5 | C27: =IF('Guest List'!$E$34="Accepted",'Guest List'!$G$34,"") -> 4 | D27: =IF('Guest List'!$E$34="Accepted",'Guest List'!$C$34,"") -> Work
A28: =IF('Guest List'!$E$35="Accepted",'Guest List'!$A$35,"") | B28: =IF('Guest List'!$E$35="Accepted",'Guest List'!$F$35,"") | C28: =IF('Guest List'!$E$35="Accepted",'Guest List'!$G$35,"") | D28: =IF('Guest List'!$E$35="Accepted",'Guest List'!$C$35,"")
A29: =IF('Guest List'!$E$36="Accepted",'Guest List'!$A$36,"") | B29: =IF('Guest List'!$E$36="Accepted",'Guest List'!$F$36,"") | C29: =IF('Guest List'!$E$36="Accepted",'Guest List'!$G$36,"") | D29: =IF('Guest List'!$E$36="Accepted",'Guest List'!$C$36,"")
A30: =IF('Guest List'!$E$37="Accepted",'Guest List'!$A$37,"") -> Fr. Antonio Reyes | B30: =IF('Guest List'!$E$37="Accepted",'Guest List'!$F$37,"") -> 0 | C30: =IF('Guest List'!$E$37="Accepted",'Guest List'!$G$37,"") -> 0 | D30: =IF('Guest List'!$E$37="Accepted",'Guest List'!$C$37,"") -> Officiant
A31: =IF('Guest List'!$E$38="Accepted",'Guest List'!$A$38,"") -> Liza Gomez | B31: =IF('Guest List'!$E$38="Accepted",'Guest List'!$F$38,"") -> 6 | C31: =IF('Guest List'!$E$38="Accepted",'Guest List'!$G$38,"") -> 1 | D31: =IF('Guest List'!$E$38="Accepted",'Guest List'!$C$38,"") -> Family Friend
A32: =IF('Guest List'!$E$39="Accepted",'Guest List'!$A$39,"") -> Arturo Gomez | B32: =IF('Guest List'!$E$39="Accepted",'Guest List'!$F$39,"") -> 6 | C32: =IF('Guest List'!$E$39="Accepted",'Guest List'!$G$39,"") -> 2 | D32: =IF('Guest List'!$E$39="Accepted",'Guest List'!$C$39,"") -> Family Friend
A33: =IF('Guest List'!$E$40="Accepted",'Guest List'!$A$40,"") -> Cielo Ramos | B33: =IF('Guest List'!$E$40="Accepted",'Guest List'!$F$40,"") -> 6 | C33: =IF('Guest List'!$E$40="Accepted",'Guest List'!$G$40,"") -> 3 | D33: =IF('Guest List'!$E$40="Accepted",'Guest List'!$C$40,"") -> Family Friend
A34: =IF('Guest List'!$E$41="Accepted",'Guest List'!$A$41,"") -> Benjie Salazar | B34: =IF('Guest List'!$E$41="Accepted",'Guest List'!$F$41,"") -> 6 | C34: =IF('Guest List'!$E$41="Accepted",'Guest List'!$G$41,"") -> 4 | D34: =IF('Guest List'!$E$41="Accepted",'Guest List'!$C$41,"") -> Family Friend
A35: =IF('Guest List'!$E$42="Accepted",'Guest List'!$A$42,"") | B35: =IF('Guest List'!$E$42="Accepted",'Guest List'!$F$42,"") | C35: =IF('Guest List'!$E$42="Accepted",'Guest List'!$G$42,"") | D35: =IF('Guest List'!$E$42="Accepted",'Guest List'!$C$42,"")
A36: =IF('Guest List'!$E$43="Accepted",'Guest List'!$A$43,"") | B36: =IF('Guest List'!$E$43="Accepted",'Guest List'!$F$43,"") | C36: =IF('Guest List'!$E$43="Accepted",'Guest List'!$G$43,"") | D36: =IF('Guest List'!$E$43="Accepted",'Guest List'!$C$43,"")
A37: =IF('Guest List'!$E$44="Accepted",'Guest List'!$A$44,"") | B37: =IF('Guest List'!$E$44="Accepted",'Guest List'!$F$44,"") | C37: =IF('Guest List'!$E$44="Accepted",'Guest List'!$G$44,"") | D37: =IF('Guest List'!$E$44="Accepted",'Guest List'!$C$44,"")
A38: =IF('Guest List'!$E$45="Accepted",'Guest List'!$A$45,"") | B38: =IF('Guest List'!$E$45="Accepted",'Guest List'!$F$45,"") | C38: =IF('Guest List'!$E$45="Accepted",'Guest List'!$G$45,"") | D38: =IF('Guest List'!$E$45="Accepted",'Guest List'!$C$45,"")
A39: =IF('Guest List'!$E$46="Accepted",'Guest List'!$A$46,"") | B39: =IF('Guest List'!$E$46="Accepted",'Guest List'!$F$46,"") | C39: =IF('Guest List'!$E$46="Accepted",'Guest List'!$G$46,"") | D39: =IF('Guest List'!$E$46="Accepted",'Guest List'!$C$46,"")
A40: =IF('Guest List'!$E$47="Accepted",'Guest List'!$A$47,"") | B40: =IF('Guest List'!$E$47="Accepted",'Guest List'!$F$47,"") | C40: =IF('Guest List'!$E$47="Accepted",'Guest List'!$G$47,"") | D40: =IF('Guest List'!$E$47="Accepted",'Guest List'!$C$47,"")
A41: =IF('Guest List'!$E$48="Accepted",'Guest List'!$A$48,"") | B41: =IF('Guest List'!$E$48="Accepted",'Guest List'!$F$48,"") | C41: =IF('Guest List'!$E$48="Accepted",'Guest List'!$G$48,"") | D41: =IF('Guest List'!$E$48="Accepted",'Guest List'!$C$48,"")
...

Sheet Run of Show
A1: Run of Show — 14 Feb 2027
A2: Sample timeline. This is what guests see on the Day-Of Hub, and what your marshals work from.
A4: Time | B4: Segment | C4: Location | D4: Owner | E4: Notes
A5: 1:00 PM | B5: Supplier call time & setup | C5: Casa Almendra | D5: Ever After coordinator | E5: Confirm florals, sound, seating
A6: 2:00 PM | B6: Checkpoint marshals briefed | C6: Reception hall | D6: Ever After coordinator | E6: Hand out printed attendee sheets
A7: 2:30 PM | B7: Guest arrival / Checkpoint 1 | C7: Main entrance | D7: Marshal A | E7: Mark Arrival column as guests enter
A8: 3:00 PM | B8: Ceremony begins | C8: Garden chapel | D8: Officiant | E8: Doors close 3:05 PM
A9: 4:00 PM | B9: Recessional & photos | C9: Garden lawn | D9: Photographer | E9: Entourage stays back
A10: 4:30 PM | B10: Cocktails / Checkpoint 2 | C10: Terrace | D10: Marshal B | E10: Gift table logging
A11: 5:30 PM | B11: Reception & dinner | C11: Reception hall | D11: Host / emcee | E11: Guests seated per table plan
A12: 6:30 PM | B12: Programme & speeches | C12: Reception hall | D12: Host / emcee | E12: Sponsors, then couple's message
A13: 7:30 PM | B13: First dance & open floor | C13: Reception hall | D13: DJ
A14: 8:30 PM | B14: Giveaways / Checkpoint 3 | C14: Exit foyer | D14: Marshal C | E14: Mark Giveaway column on release
A15: 9:00 PM | B15: Send-off | C15: Driveway | D15: Ever After coordinator | E15: Sparkler line-up
A16: 9:30 PM | B16: Teardown & supplier settle | C16: Casa Almendra | D16: Ever After coordinator | E16: Return rentals, collect gifts

Sheet Phase 0 Log
A1: Phase 0 Learning Log
A2: The real point of the manual run. Fill this in during and after the event — it decides what you build first.
A4: Task | B4: Who did it | C4: Time spent (mins) | D4: Painful? (1-5) | E4: What went wrong / what to automate
A5: Building the wedding website
A6: Writing & sending invitations
A7: Chasing RSVPs / follow-ups
A8: Updating the guest list from replies
A9: Assigning tables & seats
A10: Producing the day-of hub page
A11: Briefing checkpoint marshals
A12: Checkpoint 1 — arrival
A13: Checkpoint 2 — gift table
A14: Checkpoint 3 — giveaways
A15: Reconciling counts after the event
A16: Collecting photos/videos afterwards
... A28: · How many vendors agreed to be listed, out of how many asked?
